Workbook

Sheet Student_Brief
A1: UrbanKart Retail Pvt. Ltd. — CEO for 15 Minutes
A2: Purpose | B2: Analyze raw business data and identify the 3 biggest problems.
A3: Your role | B3: You are the CEO and management team. You have 15 minutes.
A4: Task 1 | B4: Identify the 3 biggest business problems. Support each with numbers.
A5: Task 2 | B5: Suggest likely root causes by connecting sales, profit, complaints, employees and inventory.
A6: Task 3 | B6: Recommend exactly 3 managerial decisions for the next 30 days.
A7: Rule | B7: Start with the business problem—not with a statistical technique.
A8: Period | B8: Q1 FY2026 (Apr–Jun) and Q2 FY2026 (Jul–Sep).
A9: Note | B9: Synthetic dataset for MBA experiential learning.

Sheet Sales_Orders
A1: Order_ID | B1: Order_Date | C1: Quarter | D1: Department | E1: Product_Category | F1: City | G1: Channel | H1: Units | I1: Gross_Sales_Rs | J1: Discount_Rs | K1: Net_Sales_Rs | L1: COGS_Rs | M1: Delivery_Cost_Rs | N1: Refund_Cost_Rs | O1: Other_Operating_Cost_Rs | P1: Net_Profit_Rs | Q1: Delivery_Days | R1: Return_Flag
A2: UK10001 | B2: 46186 | C2: Q1 FY2026 | D2: Electronics | E2: Laptops | F2: Nashik | G2: Online | H2: 6 | I2: 375987 | J2: 39824 | K2: 336163 | L2: 224103 | M2: 24546 | N2: 0 | O2: 56437 | P2: 31077 | Q2: 2 | R2: No
A3: UK10002 | B3: 46198 | C3: Q1 FY2026 | D3: Electronics | E3: Laptops | F3: Nashik | G3: Store | H3: 1 | I3: 166727 | J3: 11834 | K3: 154893 | L3: 94242 | M3: 10953 | N3: 0 | O3: 20030 | P3: 29668 | Q3: 4 | R3: No
A4: UK10003 | B4: 46151 | C4: Q1 FY2026 | D4: Electronics | E4: Accessories | F4: Nagpur | G4: Store | H4: 4 | I4: 280484 | J4: 51829 | K4: 228655 | L4: 140686 | M4: 16539 | N4: 0 | O4: 33903 | P4: 37527 | Q4: 2 | R4: No
A5: UK10004 | B5: 46135 | C5: Q1 FY2026 | D5: Electronics | E5: Accessories | F5: Nagpur | G5: Online | H5: 3 | I5: 235897 | J5: 22530 | K5: 213367 | L5: 138223 | M5: 17166 | N5: 0 | O5: 42847 | P5: 15131 | Q5: 2 | R5: No
A6: UK10005 | B6: 46169 | C6: Q1 FY2026 | D6: Electronics | E6: Laptops | F6: Aurangabad | G6: Store | H6: 6 | I6: 405990 | J6: 41196 | K6: 364794 | L6: 250390 | M6: 29473 | N6: 0 | O6: 62108 | P6: 22823 | Q6: 5 | R6: No
A7: UK10006 | B7: 46143 | C7: Q1 FY2026 | D7: Electronics | E7: Accessories | F7: Mumbai | G7: Online | H7: 2 | I7: 393213 | J7: 46054 | K7: 347159 | L7: 236757 | M7: 27808 | N7: 0 | O7: 61372 | P7: 21222 | Q7: 4 | R7: No
A8: UK10007 | B8: 46193 | C8: Q1 FY2026 | D8: Electronics | E8: Laptops | F8: Nagpur | G8: Store | H8: 4 | I8: 475341 | J8: 64609 | K8: 410732 | L8: 271976 | M8: 35368 | N8: 17527 | O8: 51431 | P8: 34430 | Q8: 3 | R8: Yes
A9: UK10008 | B9: 46126 | C9: Q1 FY2026 | D9: Electronics | E9: Home Electronics | F9: Mumbai | G9: Online | H9: 6 | I9: 194989 | J9: 21826 | K9: 173163 | L9: 104955 | M9: 13886 | N9: 0 | O9: 35392 | P9: 18930 | Q9: 5 | R9: No
A10: UK10009 | B10: 46172 | C10: Q1 FY2026 | D10: Electronics | E10: Accessories | F10: Nagpur | G10: Store | H10: 5 | I10: 301824 | J10: 29831 | K10: 271993 | L10: 178796 | M10: 23909 | N10: 0 | O10: 51836 | P10: 17452 | Q10: 3 | R10: No
A11: UK10010 | B11: 46194 | C11: Q1 FY2026 | D11: Electronics | E11: Accessories | F11: Aurangabad | G11: Store | H11: 6 | I11: 171871 | J11: 15566 | K11: 156305 | L11: 100236 | M11: 10321 | N11: 0 | O11: 21762 | P11: 23986 | Q11: 3 | R11: No
A12: UK10011 | B12: 46182 | C12: Q1 FY2026 | D12: Electronics | E12: Mobiles | F12: Mumbai | G12: Online | H12: 2 | I12: 238905 | J12: 26887 | K12: 212018 | L12: 140440 | M12: 13092 | N12: 0 | O12: 35176 | P12: 23310 | Q12: 5 | R12: No
A13: UK10012 | B13: 46172 | C13: Q1 FY2026 | D13: Electronics | E13: Home Electronics | F13: Pune | G13: Online | H13: 4 | I13: 327760 | J13: 31152 | K13: 296608 | L13: 193640 | M13: 21210 | N13: 0 | O13: 62073 | P13: 19685 | Q13: 4 | R13: No
... A1011: UK11010 | B1011: 46266 | C1011: Q2 FY2026 | D1011: Home Products | E1011: Decor | F1011: Aurangabad | G1011: Online | H1011: 5 | I1011: 185404 | J1011: 27972 | K1011: 157432 | L1011: 91172 | M1011: 10674 | N1011: 0 | O1011: 28817 | P1011: 26769 | Q1011: 6 | R1011: No

Sheet Complaints
A1: Complaint_ID | B1: Complaint_Date | C1: Quarter (2026) | D1: Order_ID | E1: Department | F1: Complaint_Type | G1: Severity | H1: Resolution_Days | I1: Resolved_Flag | J1: Customer_Rating_After_Resolution
A2: CMP5001 | B2: 46125 | C2: Q1 | D2: UK10104 | E2: Electronics | F2: Defective product | G2: Medium | H2: 4 | I2: Yes | J2: 5
A3: CMP5002 | B3: 46141 | C3: Q1 | D3: UK10405 | E3: Home Products | F3: Refund delay | G3: Medium | H3: 3 | I3: Yes | J3: 3
A4: CMP5003 | B4: 46188 | C4: Q1 | D4: UK10134 | E4: Electronics | F4: Late delivery | G4: Medium | H4: 3 | I4: No | J4: 5
A5: CMP5004 | B5: 46129 | C5: Q1 | D5: UK10424 | E5: Home Products | F5: Defective product | G5: Medium | H5: 2 | I5: No | J5: 3
A6: CMP5005 | B6: 46162 | C6: Q1 | D6: UK10162 | E6: Electronics | F6: Late delivery | G6: Medium | H6: 2 | I6: No | J6: 2
A7: CMP5006 | B7: 46114 | C7: Q1 | D7: UK10217 | E7: Fashion | F7: Wrong item delivered | G7: Low | H7: 1 | I7: Yes | J7: 3
A8: CMP5007 | B8: 46186 | C8: Q1 | D8: UK10304 | E8: Fashion | F8: Late delivery | G8: High | H8: 4 | I8: Yes | J8: 2
A9: CMP5008 | B9: 46186 | C9: Q1 | D9: UK10444 | E9: Home Products | F9: Wrong item delivered | G9: Medium | H9: 2 | I9: Yes | J9: 5
A10: CMP5009 | B10: 46148 | C10: Q1 | D10: UK10472 | E10: Home Products | F10: Defective product | G10: Medium | H10: 4 | I10: Yes | J10: 2
A11: CMP5010 | B11: 46145 | C11: Q1 | D11: UK10428 | E11: Home Products | F11: Defective product | G11: Critical | H11: 6 | I11: Yes | J11: 3
A12: CMP5011 | B12: 46156 | C12: Q1 | D12: UK10473 | E12: Home Products | F12: Refund delay | G12: High | H12: 1 | I12: Yes | J12: 5
A13: CMP5012 | B13: 46195 | C13: Q1 | D13: UK10007 | E13: Electronics | F13: Wrong item delivered | G13: Medium | H13: 4 | I13: Yes | J13: 4
... A675: CMP5674 | B675: 46211 | C675: Q2 | D675: UK10594 | E675: Electronics | F675: Late delivery | G675: Medium | H675: 8 | I675: Yes | J675: 3

Sheet Employees
A1: Employee_Record_ID | B1: Quarter | C1: Employee_ID | D1: Department | E1: Role | F1: Tenure_Years | G1: Monthly_Salary_Rs | H1: Satisfaction_Score_1to5 | I1: Avg_Weekly_Overtime_Hours | J1: Months_Since_Last_Promotion | K1: Exit_Flag | L1: Exit_Reason
A2: ER1001 | B2: Q1 FY2026 | C2: EMP001 | D2: Electronics | E2: Customer Support | F2: 4.2 | G2: 28000 | H2: 3 | I2: 2 | J2: 30 | K2: No
A3: ER1002 | B3: Q1 FY2026 | C3: EMP002 | D3: Electronics | E3: Sales Executive | F3: 2.1 | G3: 40000 | H3: 3 | I3: 8.6 | J3: 21 | K3: Yes | L3: Better opportunity
A4: ER1003 | B4: Q1 FY2026 | C4: EMP003 | D4: Electronics | E4: Customer Support | F4: 6.9 | G4: 47000 | H4: 3 | I4: 1.5 | J4: 3 | K4: No
A5: ER1004 | B5: Q1 FY2026 | C5: EMP004 | D5: Electronics | E5: Team Lead | F5: 3.1 | G5: 41000 | H5: 4 | I5: 5.5 | J5: 27 | K5: No
A6: ER1005 | B6: Q1 FY2026 | C6: EMP005 | D6: Electronics | E6: Customer Support | F6: 3.1 | G6: 49000 | H6: 5 | I6: 1.5 | J6: 17 | K6: No
A7: ER1006 | B7: Q1 FY2026 | C7: EMP006 | D7: Electronics | E7: Team Lead | F7: 6.4 | G7: 30000 | H7: 3 | I7: 13.6 | J7: 24 | K7: Yes | L7: Compensation
A8: ER1007 | B8: Q1 FY2026 | C8: EMP007 | D8: Electronics | E8: Sales Executive | F8: 4.4 | G8: 29000 | H8: 4 | I8: 4.5 | J8: 6 | K8: No
A9: ER1008 | B9: Q1 FY2026 | C9: EMP008 | D9: Electronics | E9: Sales Executive | F9: 6.1 | G9: 48000 | H9: 5 | I9: 2 | J9: 9 | K9: No
A10: ER1009 | B10: Q1 FY2026 | C10: EMP009 | D10: Electronics | E10: Team Lead | F10: 2.4 | G10: 27000 | H10: 5 | I10: 2.8 | J10: 17 | K10: No
A11: ER1010 | B11: Q1 FY2026 | C11: EMP010 | D11: Electronics | E11: Sales Executive | F11: 4.3 | G11: 55000 | H11: 4 | I11: 2.3 | J11: 19 | K11: No
A12: ER1011 | B12: Q1 FY2026 | C12: EMP011 | D12: Electronics | E12: Customer Support | F12: 3.6 | G12: 31000 | H12: 3 | I12: 7.5 | J12: 24 | K12: No
A13: ER1012 | B13: Q1 FY2026 | C13: EMP012 | D13: Electronics | E13: Sales Executive | F13: 7.3 | G13: 25000 | H13: 5 | I13: 1.2 | J13: 26 | K13: No
A14: ER1013 | B14: Q1 FY2026 | C14: EMP013 | D14: Electronics | E14: Sales Executive | F14: 3.4 | G14: 28000 | H14: 4 | I14: 1.7 | J14: 19 | K14: No
A15: ER1014 | B15: Q1 FY2026 | C15: EMP014 | D15: Electronics | E15: Warehouse Associate | F15: 2.8 | G15: 25000 | H15: 3 | I15: 1.4 | J15: 25 | K15: No
A16: ER1015 | B16: Q1 FY2026 | C16: EMP015 | D16: Electronics | E16: Customer Support | F16: 3.9 | G16: 34000 | H16: 4 | I16: 3.9 | J16: 19 | K16: No
A17: ER1016 | B17: Q1 FY2026 | C17: EMP016 | D17: Electronics | E17: Warehouse Associate | F17: 0.7 | G17: 58000 | H17: 4 | I17: 2.4 | J17: 25 | K17: No
A18: ER1017 | B18: Q1 FY2026 | C18: EMP017 | D18: Electronics | E18: Customer Support | F18: 3.6 | G18: 49000 | H18: 4 | I18: 2.5 | J18: 20 | K18: No
A19: ER1018 | B19: Q1 FY2026 | C19: EMP018 | D19: Electronics | E19: Warehouse Associate | F19: 1.3 | G19: 22000 | H19: 5 | I19: 3 | J19: 3 | K19: No
... A27: ER1026 | B27: Q1 FY2026 | C27: EMP026 | D27: Electronics | E27: Customer Support | F27: 4.5 | G27: 42000 | H27: 5 | I27: 1.5 | J27: 25 | K27: No
A28: ER1027 | B28: Q1 FY2026 | C28: EMP027 | D28: Electronics | E28: Sales Executive | F28: 2.7 | G28: 33000 | H28: 3 | I28: 11.3 | J28: 38 | K28: Yes | L28: Better opportunity
A29: ER1028 | B29: Q1 FY2026 | C29: EMP028 | D29: Electronics | E29: Sales Executive | F29: 6.2 | G29: 41000 | H29: 3 | I29: 10.9 | J29: 32 | K29: Yes | L29: Career growth
A30: ER1029 | B30: Q1 FY2026 | C30: EMP029 | D30: Electronics | E30: Team Lead | F30: 5 | G30: 63000 | H30: 4 | I30: 8.4 | J30: 15 | K30: No
A31: ER1030 | B31: Q1 FY2026 | C31: EMP030 | D31: Electronics | E31: Team Lead | F31: 5.3 | G31: 48000 | H31: 3 | I31: 2.6 | J31: 21 | K31: No
A32: ER1031 | B32: Q1 FY2026 | C32: EMP031 | D32: Electronics | E32: Customer Support | F32: 1.2 | G32: 46000 | H32: 4 | I32: 5.8 | J32: 26 | K32: No
A33: ER1032 | B33: Q1 FY2026 | C33: EMP032 | D33: Electronics | E33: Customer Support | F33: 7.2 | G33: 53000 | H33: 3 | I33: 2.2 | J33: 18 | K33: No
A34: ER1033 | B34: Q1 FY2026 | C34: EMP033 | D34: Electronics | E34: Warehouse Associate | F34: 6.3 | G34: 42000 | H34: 4 | I34: 5.6 | J34: 10 | K34: No
A35: ER1034 | B35: Q1 FY2026 | C35: EMP034 | D35: Electronics | E35: Customer Support | F35: 4.6 | G35: 29000 | H35: 4 | I35: 2.5 | J35: 26 | K35: No
A36: ER1035 | B36: Q1 FY2026 | C36: EMP035 | D36: Electronics | E36: Sales Executive | F36: 5.5 | G36: 38000 | H36: 5 | I36: 4.6 | J36: 3 | K36: No
A37: ER1036 | B37: Q1 FY2026 | C37: EMP036 | D37: Electronics | E37: Warehouse Associate | F37: 0.7 | G37: 51000 | H37: 3 | I37: 8.1 | J37: 30 | K37: No
A38: ER1037 | B38: Q1 FY2026 | C38: EMP037 | D38: Electronics | E38: Warehouse Associate | F38: 1.2 | G38: 48000 | H38: 3 | I38: 5.1 | J38: 29 | K38: No
A39: ER1038 | B39: Q1 FY2026 | C39: EMP038 | D39: Electronics | E39: Sales Executive | F39: 4.9 | G39: 64000 | H39: 2 | I39: 12.7 | J39: 37 | K39: Yes | L39: Compensation
A40: ER1039 | B40: Q1 FY2026 | C40: EMP039 | D40: Electronics | E40: Sales Executive | F40: 2.1 | G40: 65000 | H40: 3 | I40: 7.8 | J40: 31 | K40: No
A41: ER1040 | B41: Q1 FY2026 | C41: EMP040 | D41: Electronics | E41: Team Lead | F41: 6.8 | G41: 29000 | H41: 5 | I41: 5.6 | J41: 22 | K41: No
A42: ER1041 | B42: Q1 FY2026 | C42: EMP041 | D42: Fashion | E42: Sales Executive | F42: 6.2 | G42: 26000 | H42: 5 | I42: 8.7 | J42: 32 | K42: No
A43: ER1042 | B43: Q1 FY2026 | C43: EMP042 | D43: Fashion | E43: Store Associate | F43: 1.6 | G43: 29000 | H43: 4 | I43: 13.2 | J43: 25 | K43: Yes | L43: Manager issues
A44: ER1043 | B44: Q1 FY2026 | C44: EMP043 | D44: Fashion | E44: Store Associate | F44: 4.5 | G44: 50000 | H44: 4 | I44: 5.2 | J44: 26 | K44: No
A45: ER1044 | B45: Q1 FY2026 | C45: EMP044 | D45: Fashion | E45: Sales Executive | F45: 4.3 | G45: 25000 | H45: 5 | I45: 4 | J45: 32 | K45: No
A46: ER1045 | B46: Q1 FY2026 | C46: EMP045 | D46: Fashion | E46: Team Lead | F46: 3.8 | G46: 52000 | H46: 3 | I46: 3.1 | J46: 4 | K46: No
A47: ER1046 | B47: Q1 FY2026 | C47: EMP046 | D47: Fashion | E47: Store Associate | F47: 3.2 | G47: 27000 | H47: 2 | I47: 12.6 | J47: 21 | K47: Yes | L47: Compensation
...

Sheet Inventory
A1: Snapshot_Date | B1: Quarter | C1: SKU | D1: Department | E1: Product_Category | F1: Stock_On_Hand_Units | G1: Unit_Cost_Rs | H1: Inventory_Value_Rs | I1: Avg_Daily_COGS_Rs | J1: Days_On_Hand | K1: Forecast_Demand_30D_Units | L1: Reorder_Level_Units | M1: Inventory_Status
A2: 46203 | B2: Q1 FY2026 | C2: SKU0001 | D2: Electronics | E2: Accessories | F2: 222 | G2: 3257 | H2: 723054 | I2: 10955.36 | J2: 66 | K2: 184 | L2: 112 | M2: Normal
A3: 46203 | B3: Q1 FY2026 | C3: SKU0002 | D3: Electronics | E3: Home Electronics | F3: 275 | G3: 6691 | H3: 1840025 | I3: 36078.92 | J3: 51 | K3: 100 | L3: 52 | M3: Normal
A4: 46203 | B4: Q1 FY2026 | C4: SKU0003 | D4: Electronics | E4: Mobiles | F4: 101 | G4: 7766 | H4: 784366 | I4: 16007.47 | J4: 49 | K4: 45 | L4: 21 | M4: Normal
A5: 46203 | B5: Q1 FY2026 | C5: SKU0004 | D5: Electronics | E5: Laptops | F5: 231 | G5: 7302 | H5: 1686762 | I5: 24805.32 | J5: 68 | K5: 123 | L5: 56 | M5: Normal
A6: 46203 | B6: Q1 FY2026 | C6: SKU0005 | D6: Electronics | E6: Laptops | F6: 391 | G6: 7652 | H6: 2991932 | I6: 58665.33 | J6: 51 | K6: 138 | L6: 75 | M6: Normal
A7: 46203 | B7: Q1 FY2026 | C7: SKU0006 | D7: Electronics | E7: Mobiles | F7: 205 | G7: 7831 | H7: 1605355 | I7: 32762.35 | J7: 49 | K7: 142 | L7: 84 | M7: Normal
A8: 46203 | B8: Q1 FY2026 | C8: SKU0007 | D8: Electronics | E8: Accessories | F8: 192 | G8: 4352 | H8: 835584 | I8: 13926.4 | J8: 60 | K8: 151 | L8: 84 | M8: Normal
A9: 46203 | B9: Q1 FY2026 | C9: SKU0008 | D9: Electronics | E9: Laptops | F9: 82 | G9: 2089 | H9: 171298 | I9: 2854.97 | J9: 60 | K9: 54 | L9: 36 | M9: Normal
A10: 46203 | B10: Q1 FY2026 | C10: SKU0009 | D10: Electronics | E10: Accessories | F10: 384 | G10: 4259 | H10: 1635456 | I10: 35553.39 | J10: 46 | K10: 305 | L10: 210 | M10: Normal
A11: 46203 | B11: Q1 FY2026 | C11: SKU0010 | D11: Electronics | E11: Mobiles | F11: 227 | G11: 7725 | H11: 1753575 | I11: 30234.05 | J11: 58 | K11: 157 | L11: 84 | M11: Normal
A12: 46203 | B12: Q1 FY2026 | C12: SKU0011 | D12: Electronics | E12: Mobiles | F12: 235 | G12: 4677 | H12: 1099095 | I12: 23893.37 | J12: 46 | K12: 89 | L12: 61 | M12: Normal
A13: 46203 | B13: Q1 FY2026 | C13: SKU0012 | D13: Electronics | E13: Mobiles | F13: 379 | G13: 1657 | H13: 628003 | I13: 10827.64 | J13: 58 | K13: 213 | L13: 144 | M13: Normal
... A181: 46295 | B181: Q2 FY2026 | C181: SKU0180 | D181: Home Products | E181: Cleaning | F181: 302 | G181: 1018 | H181: 307436 | I181: 5123.93 | J181: 60 | K181: 127 | L181: 72 | M181: Normal

Sheet Instructor_Summary
A1: UrbanKart Retail Pvt. Ltd. — Instructor Summary
A3: KPI | B3: Q1 FY2026 | C3: Q2 FY2026 | D3: Change | E3: Interpretation
A4: Sales Revenue | B4: =SUMIFS(Sales_Orders!$K$2:$K$1011,Sales_Orders!$C$2:$C$1011,"Q1 FY2026") -> 121000000 | C4: =SUMIFS(Sales_Orders!$K$2:$K$1011,Sales_Orders!$C$2:$C$1011,"Q2 FY2026") -> 128000000 | D4: =C4/B4-1 -> 0.05785124 | E4: Sales grew modestly.
A5: Net Profit | B5: =SUMIFS(Sales_Orders!$P$2:$P$1011,Sales_Orders!$C$2:$C$1011,"Q1 FY2026") -> 13085240 | C5: =SUMIFS(Sales_Orders!$P$2:$P$1011,Sales_Orders!$C$2:$C$1011,"Q2 FY2026") -> 8157528 | D5: =C5/B5-1 -> -0.37658553 | E5: Profit fell sharply despite higher sales.
A6: Customer Complaints | B6: =COUNTIF(Complaints!$C$2:$C$675,"Q1 FY2026") -> 0 | C6: =COUNTIF(Complaints!$C$2:$C$675,"Q2 FY2026") -> 0 | D6: =C6/B6-1 -> #DIV/0! | E6: Complaints rose substantially.
A7: Employee Turnover | B7: =COUNTIFS(Employees!$B$2:$B$201,"Q1 FY2026",Employees!$K$2:$K$201,"Yes")/COUNTIF(Employees!$B$2:$B$201,"Q1 FY2026") -> 0.14 | C7: =COUNTIFS(Employees!$B$2:$B$201,"Q2 FY2026",Employees!$K$2:$K$201,"Yes")/COUNTIF(Employees!$B$2:$B$201,"Q2 FY2026") -> 0.21 | D7: =C7/B7-1 -> 0.5 | E7: Turnover increased to a critical level.
A8: Inventory Days | B8: =SUMIFS(Inventory!$J$2:$J$181,Inventory!$B$2:$B$181,"Q1 FY2026")/COUNTIF(Inventory!$B$2:$B$181,"Q1 FY2026") -> 49.577778 | C8: =SUMIFS(Inventory!$J$2:$J$181,Inventory!$B$2:$B$181,"Q2 FY2026")/COUNTIF(Inventory!$B$2:$B$181,"Q2 FY2026") -> 74.633333 | D8: =C8/B8-1 -> 0.50537875 | E8: Inventory holding increased materially.
A11: Department | B11: Q2 Sales | C11: Q2 Profit | D11: Q2 Complaints | E11: Q2 Inventory Days
A12: Electronics | B12: =SUMIFS(Sales_Orders!$K$2:$K$1011,Sales_Orders!$C$2:$C$1011,"Q2 FY2026",Sales_Orders!$D$2:$D$1011,A12) -> 56000000 | C12: =SUMIFS(Sales_Orders!$P$2:$P$1011,Sales_Orders!$C$2:$C$1011,"Q2 FY2026",Sales_Orders!$D$2:$D$1011,A12) -> 2100000 | D12: =COUNTIFS(Complaints!$C$2:$C$675,"Q2 FY2026",Complaints!$E$2:$E$675,A12) -> 0 | E12: =SUMIFS(Inventory!$J$2:$J$181,Inventory!$B$2:$B$181,"Q2 FY2026",Inventory!$D$2:$D$181,A12)/COUNTIFS(Inventory!$B$2:$B$181,"Q2 FY2026",Inventory!$D$2:$D$181,A12) -> 92
A13: Fashion | B13: =SUMIFS(Sales_Orders!$K$2:$K$1011,Sales_Orders!$C$2:$C$1011,"Q2 FY2026",Sales_Orders!$D$2:$D$1011,A13) -> 41000000 | C13: =SUMIFS(Sales_Orders!$P$2:$P$1011,Sales_Orders!$C$2:$C$1011,"Q2 FY2026",Sales_Orders!$D$2:$D$1011,A13) -> 3000000 | D13: =COUNTIFS(Complaints!$C$2:$C$675,"Q2 FY2026",Complaints!$E$2:$E$675,A13) -> 0 | E13: =SUMIFS(Inventory!$J$2:$J$181,Inventory!$B$2:$B$181,"Q2 FY2026",Inventory!$D$2:$D$181,A13)/COUNTIFS(Inventory!$B$2:$B$181,"Q2 FY2026",Inventory!$D$2:$D$181,A13) -> 61.9
A14: Home Products | B14: =SUMIFS(Sales_Orders!$K$2:$K$1011,Sales_Orders!$C$2:$C$1011,"Q2 FY2026",Sales_Orders!$D$2:$D$1011,A14) -> 31000000 | C14: =SUMIFS(Sales_Orders!$P$2:$P$1011,Sales_Orders!$C$2:$C$1011,"Q2 FY2026",Sales_Orders!$D$2:$D$1011,A14) -> 3057528 | D14: =COUNTIFS(Complaints!$C$2:$C$675,"Q2 FY2026",Complaints!$E$2:$E$675,A14) -> 0 | E14: =SUMIFS(Inventory!$J$2:$J$181,Inventory!$B$2:$B$181,"Q2 FY2026",Inventory!$D$2:$D$181,A14)/COUNTIFS(Inventory!$B$2:$B$181,"Q2 FY2026",Inventory!$D$2:$D$181,A14) -> 70
